Workbook

Sheet Assumptions
A1: HUL DCF Model — Assumptions
A2: Base Year: FY25
A3: Forecast Period: FY26E to FY30E
A5: MACRO ASSUMPTIONS
A6: India Nominal GDP Growth | B6: 0.105 | D6: Real 6% + CPI 4.5%
A7: India CPI Inflation | B7: 0.045 | D7: RBI medium-term target
A8: 10-Year G-Sec Yield (Rf) | B8: 0.0685 | D8: Risk-free rate for WACC
A9: India Equity Risk Premium | B9: 0.06 | D9: Damodaran Jan 2025
A10: Terminal Growth Rate | B10: 0.05 | D10: Must be below nominal GDP
A12: REVENUE GROWTH ASSUMPTIONS
A13: Home Care — Annual Growth | B13: 0.05 | C13: Mature segment, premiumisation led
A14: Beauty & Personal Care — Annual Growth | B14: 0.08 | C14: Minimalist acquisition + D2C growth
A15: Foods & Refreshment — Annual Growth | B15: 0.075 | C15: Post ice-cream demerger adjusted
A16: Others (Exports) — Annual Growth | B16: 0.03 | C16: Non-core, flat assumed
A18: FY25 Base Revenue (₹ Cr) | B18: 64120 | C18: Audited FY25 total — update if needed
A20: MARGIN ASSUMPTIONS
A21: Gross Margin % | B21: 0.495 | C21: FY25 actual ~49.8%, slight compression
A22: EBITDA Margin % | B22: 0.23 | C22: Mgmt guided 22–23% band
A23: Depreciation (% of Revenue) | B23: 0.025 | C23: Historical average
A24: EBIT Margin % | B24: =B22-B23 -> 0.205 | C24: Auto-calculated
A25: Effective Tax Rate | B25: 0.25 | C25: New tax regime, incl. deferred tax
A26: Other Income (₹ Cr, flat) | B26: 1200 | C26: Interest income on cash surplus
A29: WORKING CAPITAL ASSUMPTIONS
A30: Debtor Days (DSO) | B30: 12 | C30: Days to collect from customers
A31: Inventory Days (DIO) | B31: 38 | C31: Days inventory held
A32: Payable Days (DPO) | B32: 67 | C32: Days HUL takes to pay suppliers
A33: Cash Conversion Cycle | B33: =B30+B31-B32 -> -17 | C33: Negative = structural advantage
A36: CAPEX ASSUMPTIONS
A37: Capex as % of Revenue | B37: 0.028 | C37: HUL is asset-light, 5Y avg ~2.5–3%
A38: Depreciation as % of Revenue | B38: 0.025 | C38: Historical average
A41: WACC INPUTS
A42: Risk-Free Rate | B42: 0.0685
A43: Equity Risk Premium | B43: =B9 -> 0.06
A44: Beta (HUL vs Nifty 50) | B44: 0.55
A45: Cost of Equity (Ke) | B45: =B42+(B44*B43) -> 0.1015
A46: Pre-Tax Cost of Debt (Kd) | B46: 0.075
A47: Tax Rate | B47: =B25 -> 0.25
A48: Post-Tax Cost of Debt | B48: =B46*(1-B47) -> 0.05625
A49: Debt Weight (Wd) | B49: 0.02
A50: Equity Weight (We) | B50: =1-B49 -> 0.98
...

Sheet Revenue
A1: HUL — Revenue Model
A2: All figures in ₹ Crore
A4: Segment | B4: FY23A | C4: FY24A | D4: FY25A | E4: FY26E | F4: FY27E | G4: FY28E | H4: FY29E | I4: FY30E
A5: Home Care | B5: 21897 | C5: 21900 | D5: 22972 | E5: =D5*(1+Assumptions!$B$13) -> 24120.6 | F5: =E5*(1+Assumptions!$B$13) -> 25326.63 | G5: =F5*(1+Assumptions!$B$13) -> 26592.962 | H5: =G5*(1+Assumptions!$B$13) -> 27922.61 | I5: =H5*(1+Assumptions!$B$13) -> 29318.74
A6: Beauty & Personal Care | B6: 22042 | C6: 22165 | D6: 22448 | E6: =D6*(1+Assumptions!$B$14) -> 24243.84 | F6: =E6*(1+Assumptions!$B$14) -> 26183.347 | G6: =F6*(1+Assumptions!$B$14) -> 28278.015 | H6: =G6*(1+Assumptions!$B$14) -> 30540.256 | I6: =H6*(1+Assumptions!$B$14) -> 32983.477
A7: Foods & Refreshment | B7: 15624 | C7: 17831 | D7: 16900 | E7: =D7*(1+Assumptions!$B$15) -> 18167.5 | F7: =E7*(1+Assumptions!$B$15) -> 19530.062 | G7: =F7*(1+Assumptions!$B$15) -> 20994.817 | H7: =G7*(1+Assumptions!$B$15) -> 22569.428 | I7: =H7*(1+Assumptions!$B$15) -> 24262.136
A8: Others (Exports) | B8: 1017 | C8: 2227 | D8: 1800 | E8: =D8*(1+Assumptions!$B$16) -> 1854 | F8: =E8*(1+Assumptions!$B$16) -> 1909.62 | G8: =F8*(1+Assumptions!$B$16) -> 1966.9086 | H8: =G8*(1+Assumptions!$B$16) -> 2025.9159 | I8: =H8*(1+Assumptions!$B$16) -> 2086.6933
A9: Total Revenue | B9: =SUM(B5:B8) -> 60580 | C9: =SUM(C5:C8) -> 64123 | D9: =SUM(D5:D8) -> 64120 | E9: =SUM(E5:E8) -> 68385.94 | F9: =SUM(F5:F8) -> 72949.66 | G9: =SUM(G5:G8) -> 77832.702 | H9: =SUM(H5:H8) -> 83058.21 | I9: =SUM(I5:I8) -> 88651.046
A10: YoY Growth % | B10: — | C10: =(C9/B9)-1 -> 0.058484648 | D10: =(D9/C9)-1 -> -4.6785085e-05 | E10: =(E9/D9)-1 -> 0.066530568 | F10: =(F9/E9)-1 -> 0.066734766 | G10: =(G9/F9)-1 -> 0.066937153 | H10: =(H9/G9)-1 -> 0.06713769 | I10: =(I9/H9)-1 -> 0.067336337

Sheet p&l
A1: HUL — Income Statement (P&L)
A2: All figures in ₹ Crore
A4: Line Item | B4: FY23A | C4: FY24A | D4: FY25A | E4: FY26E | F4: FY27E | G4: FY28E | H4: FY29E | I4: FY30E
A5: Revenue | B5: 60580 | C5: 64123 | D5: 64120 | E5: =Revenue!E9 -> 68385.94 | F5: =Revenue!F9 -> 72949.66 | G5: =Revenue!G9 -> 77832.702 | H5: =Revenue!H9 -> 83058.21 | I5: =Revenue!I9 -> 88651.046
A6: Gross Profit | B6: 28172 | C6: 31185 | D6: 31932 | E6: =E5*Assumptions!$B$21 -> 33851.04 | F6: =F5*Assumptions!$B$21 -> 36110.082 | G6: =G5*Assumptions!$B$21 -> 38527.188 | H6: =H5*Assumptions!$B$21 -> 41113.814 | I6: =I5*Assumptions!$B$21 -> 43882.268
A7: Gross Margin % | B7: =B6/B5 -> 0.46503797 | C7: =C6/C5 -> 0.48633096 | D7: =D6/D5 -> 0.49800374 | E7: =E6/E5 -> 0.495 | F7: =F6/F5 -> 0.495 | G7: =G6/G5 -> 0.495 | H7: =H6/H5 -> 0.495 | I7: =I6/I5 -> 0.495
A8: EBITDA | B8: 13728 | C8: 14641 | D8: 15069 | E8: =E5*Assumptions!$B$22 -> 15728.766 | F8: =F5*Assumptions!$B$22 -> 16778.422 | G8: =G5*Assumptions!$B$22 -> 17901.522 | H8: =H5*Assumptions!$B$22 -> 19103.388 | I8: =I5*Assumptions!$B$22 -> 20389.741
A9: EBITDA Margin % | B9: =B8/B5 -> 0.22660944 | C9: =C8/C5 -> 0.22832681 | D9: =D8/D5 -> 0.23501248 | E9: =E8/E5 -> 0.23 | F9: =F8/F5 -> 0.23 | G9: =G8/G5 -> 0.23 | H9: =H8/H5 -> 0.23 | I9: =I8/I5 -> 0.23
A10: Depreciation | B10: 1422 | C10: 1531 | D10: 1620 | E10: =E5*Assumptions!$B$23 -> 1709.6485 | F10: =F5*Assumptions!$B$23 -> 1823.7415 | G10: =G5*Assumptions!$B$23 -> 1945.8176 | H10: =H5*Assumptions!$B$23 -> 2076.4553 | I10: =I5*Assumptions!$B$23 -> 2216.2761
A11: EBIT | B11: =B8-B10 -> 12306 | C11: =C8-C10 -> 13110 | D11: =D8-D10 -> 13449 | E11: =E8-E10 -> 14019.118 | F11: =F8-F10 -> 14954.68 | G11: =G8-G10 -> 15955.704 | H11: =H8-H10 -> 17026.933 | I11: =I8-I10 -> 18173.464
A12: EBIT Margin % | B12: =B11/B5 -> 0.20313635 | C12: =C11/C5 -> 0.20445082 | D12: =D11/D5 -> 0.20974735 | E12: =E11/E5 -> 0.205 | F12: =F11/F5 -> 0.205 | G12: =G11/G5 -> 0.205 | H12: =H11/H5 -> 0.205 | I12: =I11/I5 -> 0.205
A13: Other Income | B13: 1169 | C13: 1270 | D13: 1272 | E13: =Assumptions!$B$26 -> 1200 | F13: =Assumptions!$B$26 -> 1200 | G13: =Assumptions!$B$26 -> 1200 | H13: =Assumptions!$B$26 -> 1200 | I13: =Assumptions!$B$26 -> 1200
A14: PBT | B14: =B11+B13 -> 13475 | C14: =C11+C13 -> 14380 | D14: =D11+D13 -> 14721 | E14: =E11+E13 -> 15219.118 | F14: =F11+F13 -> 16154.68 | G14: =G11+G13 -> 17155.704 | H14: =H11+H13 -> 18226.933 | I14: =I11+I13 -> 19373.464
A15: Tax | B15: =B14*Assumptions!$B$25 -> 3368.75 | C15: =C14*Assumptions!$B$25 -> 3595 | D15: =D14*Assumptions!$B$25 -> 3680.25 | E15: =E14*Assumptions!$B$25 -> 3804.7794 | F15: =F14*Assumptions!$B$25 -> 4038.6701 | G15: =G14*Assumptions!$B$25 -> 4288.926 | H15: =H14*Assumptions!$B$25 -> 4556.7333 | I15: =I14*Assumptions!$B$25 -> 4843.3661
A16: PAT | B16: =B14-B15 -> 10106.25 | C16: =C14-C15 -> 10785 | D16: =D14-D15 -> 11040.75 | E16: =E14-E15 -> 11414.338 | F16: =F14-F15 -> 12116.01 | G16: =G14-G15 -> 12866.778 | H16: =H14-H15 -> 13670.2 | I16: =I14-I15 -> 14530.098
A17: PAT Margin % | B17: =B16/B5 -> 0.16682486 | C17: =C16/C5 -> 0.16819238 | D17: =D16/D5 -> 0.17218886 | E17: =E16/E5 -> 0.1669106 | F17: =F16/F5 -> 0.16608727 | G17: =G16/G5 -> 0.16531326 | H17: =H16/H5 -> 0.16458577 | I17: =I16/I5 -> 0.16390216

Sheet BS
A1: HUL — Balance Sheet
A2: All figures in ₹ Crore
A4: Line Item | B4: FY23A | C4: FY24A | D4: FY25A | E4: FY26E | F4: FY27E | G4: FY28E | H4: FY29E | I4: FY30E
A5: ASSETS
A6: Net Fixed Assets | B6: 5246 | C6: 5404 | D6: 5500 | E6: =D6 + (Revenue!E9*Assumptions!$B$37) - (Revenue!E9*Assumptions!$B$38) -> 5705.1578 | F6: =E6 + (Revenue!F9*Assumptions!$B$37) - (Revenue!F9*Assumptions!$B$38) -> 5924.0068 | G6: =F6 + (Revenue!G9*Assumptions!$B$37) - (Revenue!G9*Assumptions!$B$38) -> 6157.5049 | H6: =G6 + (Revenue!H9*Assumptions!$B$37) - (Revenue!H9*Assumptions!$B$38) -> 6406.6795 | I6: =H6 + (Revenue!I9*Assumptions!$B$37) - (Revenue!I9*Assumptions!$B$38) -> 6672.6327
A7: Capital WIP | B7: 312 | C7: 289 | D7: 300 | E7: =D7 -> 300 | F7: =E7 -> 300 | G7: =F7 -> 300 | H7: =G7 -> 300 | I7: =H7 -> 300
A8: Trade Receivables | B8: 1820 | C8: 1690 | D8: 1850 | E8: =(Assumptions!$B$30/365)*'p&l'!E5 -> 2248.3049 | F8: =(Assumptions!$B$30/365)*'p&l'!F5 -> 2398.345 | G8: =(Assumptions!$B$30/365)*'p&l'!G5 -> 2558.8834 | H8: =(Assumptions!$B$30/365)*'p&l'!H5 -> 2730.6809 | I8: =(Assumptions!$B$30/365)*'p&l'!I5 -> 2914.5549
A9: Inventory | B9: 2980 | C9: 2830 | D9: 2950 | E9: =(Assumptions!$B$31/365)*'p&l'!E5 -> 7119.6321 | F9: =(Assumptions!$B$31/365)*'p&l'!F5 -> 7594.7591 | G9: =(Assumptions!$B$31/365)*'p&l'!G5 -> 8103.1306 | H9: =(Assumptions!$B$31/365)*'p&l'!H5 -> 8647.1561 | I9: =(Assumptions!$B$31/365)*'p&l'!I5 -> 9229.4239
A10: Cash & Equivalents | B10: 1243 | C10: 1484 | D10: 1600 | E10: =D10 -> 1600 | F10: =E10 -> 1600 | G10: =F10 -> 1600 | H10: =G10 -> 1600 | I10: =H10 -> 1600
A11: Other Current Assets | B11: 2100 | C11: 2200 | D11: 2300 | E11: =D11*(1+(Revenue!E9/Revenue!D9-1)) -> 2453.0203 | F11: =E11*(1+(Revenue!F9/Revenue!E9-1)) -> 2616.722 | G11: =F11*(1+(Revenue!G9/Revenue!F9-1)) -> 2791.878 | H11: =G11*(1+(Revenue!H9/Revenue!G9-1)) -> 2979.3182 | I11: =H11*(1+(Revenue!I9/Revenue!H9-1)) -> 3179.9346
A12: Total Assets | B12: =SUM(B6:B11) -> 13701 | C12: =SUM(C6:C11) -> 13897 | D12: =SUM(D6:D11) -> 14500 | E12: =SUM(E6:E11) -> 19426.115 | F12: =SUM(F6:F11) -> 20433.833 | G12: =SUM(G6:G11) -> 21511.397 | H12: =SUM(H6:H11) -> 22663.835 | I12: =SUM(I6:I11) -> 23896.546
A14: LIABILITIES
A15: Trade Payables | B15: 9834 | C15: 9972 | D15: 10200 | E15: =(Assumptions!$B$32/365)*'p&l'!E5 -> 12553.036 | F15: =(Assumptions!$B$32/365)*'p&l'!F5 -> 13390.759 | G15: =(Assumptions!$B$32/365)*'p&l'!G5 -> 14287.099 | H15: =(Assumptions!$B$32/365)*'p&l'!H5 -> 15246.302 | I15: =(Assumptions!$B$32/365)*'p&l'!I5 -> 16272.932
A16: Short Term Debt | B16: 148 | C16: 78 | D16: 50 | E16: =0 -> 0 | F16: =0 -> 0 | G16: =0 -> 0 | H16: =0 -> 0 | I16: =0 -> 0
A17: Other Current Liabilities | B17: 3200 | C17: 3400 | D17: 3500 | E17: =D17*(1+(Revenue!E9/Revenue!D9-1)) -> 3732.857 | F17: =E17*(1+(Revenue!F9/Revenue!E9-1)) -> 3981.9683 | G17: =F17*(1+(Revenue!G9/Revenue!F9-1)) -> 4248.5099 | H17: =G17*(1+(Revenue!H9/Revenue!G9-1)) -> 4533.7451 | I17: =H17*(1+(Revenue!I9/Revenue!H9-1)) -> 4839.0309
A18: Total Equity | B18: 10354 | C18: 10521 | D18: 10800 | E18: =D18 + ('p&l'!E16*0.05) -> 11370.717 | F18: =E18 + ('p&l'!F16*0.05) -> 11976.517 | G18: =F18 + ('p&l'!G16*0.05) -> 12619.856 | H18: =G18 + ('p&l'!H16*0.05) -> 13303.366 | I18: =H18 + ('p&l'!I16*0.05) -> 14029.871
A19: Total Liabilities & Equity | B19: =SUM(B15:B18) -> 23536 | C19: =SUM(C15:C18) -> 23971 | D19: =SUM(D15:D18) -> 24550 | E19: =SUM(E15:E18) -> 27656.609 | F19: =SUM(F15:F18) -> 29349.245 | G19: =SUM(G15:G18) -> 31155.465 | H19: =SUM(H15:H18) -> 33083.413 | I19: =SUM(I15:I18) -> 35141.834
A21: NET WORKING CAPITAL CHECK
A22: NWC = Receivables + Inventory − Payables
A23: FY26E NWC | B23: =E8+E9-E15 -> -3185.0986
A25: Capex (₹ Cr) | E25: =Revenue!E9*Assumptions!$B$37 -> 1914.8063 | F25: =Revenue!F9*Assumptions!$B$37 -> 2042.5905 | G25: =Revenue!G9*Assumptions!$B$37 -> 2179.3157 | H25: =Revenue!H9*Assumptions!$B$37 -> 2325.6299 | I25: =Revenue!I9*Assumptions!$B$37 -> 2482.2293
A26: NWC (Receivables + Inventory − Payables) | D26: =D8+D9-D15 -> -5400 | E26: =E8+E9-E15 -> -3185.0986 | F26: =F8+F9-F15 -> -3397.6554 | G26: =G8+G9-G15 -> -3625.0848 | H26: =H8+H9-H15 -> -3868.4646 | I26: =I8+I9-I15 -> -4128.9528
A27: Change in NWC (vs prior year) | E27: =E26-D26 -> 2214.9014 | F27: =F26-E26 -> -212.55681 | G27: =G26-F26 -> -227.42938 | H27: =H26-G26 -> -243.37982 | I27: =I26-H26 -> -260.48823

Sheet FCF
A1: HUL — Free Cash Flow to Firm (FCFF)
A2: All figures in ₹ Crore
A4: Line Item | E4: FY26E | F4: FY27E | G4: FY28E | H4: FY29E | I4: FY30E
A5: EBIT | E5: =('p&l'!E11) -> 14019.118 | F5: =('p&l'!F11) -> 14954.68 | G5: =('p&l'!G11) -> 15955.704 | H5: =('p&l'!H11) -> 17026.933 | I5: =('p&l'!I11) -> 18173.464
A6: Tax on EBIT (25%) | E6: =E5*Assumptions!$B$25 -> 3504.7794 | F6: =F5*Assumptions!$B$25 -> 3738.6701 | G6: =G5*Assumptions!$B$25 -> 3988.926 | H6: =H5*Assumptions!$B$25 -> 4256.7333 | I6: =I5*Assumptions!$B$25 -> 4543.3661
A7: NOPAT = EBIT(1−t) | E7: =E5-E6 -> 10514.338 | F7: =F5-F6 -> 11216.01 | G7: =G5-G6 -> 11966.778 | H7: =H5-H6 -> 12770.2 | I7: =I5-I6 -> 13630.098
A8: Depreciation | E8: =('p&l'!E10) -> 1709.6485 | F8: =('p&l'!F10) -> 1823.7415 | G8: =('p&l'!G10) -> 1945.8176 | H8: =('p&l'!H10) -> 2076.4553 | I8: =('p&l'!I10) -> 2216.2761
A9: Less: Capex | E9: =(BS!E25) -> 1914.8063 | F9: =(BS!F25) -> 2042.5905 | G9: =(BS!G25) -> 2179.3157 | H9: =(BS!H25) -> 2325.6299 | I9: =(BS!I25) -> 2482.2293
A10: Less: Change in NWC | E10: =(BS!E27) -> 2214.9014 | F10: =(BS!F27) -> -212.55681 | G10: =(BS!G27) -> -227.42938 | H10: =(BS!H27) -> -243.37982 | I10: =(BS!I27) -> -260.48823
A12: FREE CASH FLOW TO FIRM (FCFF) | E12: =E7+E8-E9-E10 -> 8094.279 | F12: =F7+F8-F9-F10 -> 11209.718 | G12: =G7+G8-G9-G10 -> 11960.709 | H12: =H7+H8-H9-H10 -> 12764.405 | I12: =I7+I8-I9-I10 -> 13624.633
A13: FCFF Growth % | F13: =(F12/E12)-1 -> 0.38489394 | G13: =(G12/F12)-1 -> 0.066994659 | H13: =(H12/G12)-1 -> 0.067194656 | I13: =(I12/H12)-1 -> 0.067392752
A14: FCFF Margin % | E14: =E12/'p&l'!E5 -> 0.11836174 | F14: =F12/'p&l'!F5 -> 0.15366375 | G14: =G12/'p&l'!G5 -> 0.15367203 | H14: =H12/'p&l'!H5 -> 0.15368023 | I14: =I12/'p&l'!I5 -> 0.15368835

Sheet DCF
A1: HUL — DCF Valuation
A2: All figures in ₹ Crore
A4: Line Item | E4: FY26E | F4: FY27E | G4: FY28E | H4: FY29E | I4: FY30E
A5: FCFF | E5: =FCF!E12 -> 8094.279 | F5: =FCF!F12 -> 11209.718 | G5: =FCF!G12 -> 11960.709 | H5: =FCF!H12 -> 12764.405 | I5: =FCF!I12 -> 13624.633
A6: Discount Period (Year) | E6: 1 | F6: 2 | G6: 3 | H6: 4 | I6: 5
A7: Discount Factor | E7: =1/(1+$B$32)^E6 -> 0.90859944 | F7: =1/(1+$B$32)^F6 -> 0.82555294 | G7: =1/(1+$B$32)^G6 -> 0.75009694 | H7: =1/(1+$B$32)^H6 -> 0.68153766 | I7: =1/(1+$B$32)^I6 -> 0.61924473
A8: PV of FCFF | E8: =E5*E7 -> 7354.4574 | F8: =F5*F7 -> 9254.2157 | G8: =G5*G7 -> 8971.6914 | H8: =H5*H7 -> 8699.4227 | I8: =I5*I7 -> 8436.9825
A9: Total PV of FCFFs | E9: =SUM(E8:I8) -> 42716.77
A12: TERMINAL VALUE — METHOD 1 (Gordon Growth)
A13: Terminal FCFF (FY31E) | E13: =FCF!I12*(1+$B$31) -> 14305.865
A14: Terminal Value (GGM) | E14: =E13/($B$32-$B$31) -> 282752.55
A15: PV of Terminal Value (GGM) | E15: =E14*I7 -> 175093.02
A17: TERMINAL VALUE — METHOD 2 (Exit Multiple)
A18: Terminal Value (35× FY30 EBITDA) | E18: =('p&l'!I8)*35 -> 713640.92
A19: PV of Terminal Value (Exit Multiple) | E19: =E18*I7 -> 441918.38
A22: Average PV of Terminal Value | E22: =(E15+E19)/2 -> 308505.7
A23: Enterprise Value (EV) | E23: =E9+E22 -> 351222.47
A24: Less: Net Debt (Debt − Cash) | E24: =BS!D16-BS!D10 -> -1550
A25: Equity Value | E25: =E23-E24 -> 352772.47
A26: Shares Outstanding (Crore) | E26: =234 -> 234
A27: Intrinsic Value per Share (₹) | E27: =(E25/E26) -> 1507.5747
A28: Current Market Price (₹) | E28: =2370 -> 2370
A29: Upside / (Downside) % | E29: =(E27/E28)-1 -> -0.36389254
A31: Terminal Growth Rate (link) | B31: =Assumptions!$B$10 -> 0.05
A32: WACC (link) | B32: =Assumptions!$B$51 -> 0.100595
A33: SENSITIVITY ANALYSIS — Intrinsic Value per Share (₹)
A34: WACC (rows) vs Terminal Growth Rate (columns)
A35: =E27 -> 1507.5747 | B35: 0.04 | C35: 0.045 | D35: 0.05 | E35: 0.055 | F35: 0.06 | G35: 0.065 | H35: 0.07
A36: 0.08 | B36: 1752.9744 | C36: 1829.3977 | D36: 1931.2955 | E36: 2073.9523 | F36: 2287.9376 | G36: 2644.5798 | H36: 3357.8642
A37: 0.085 | B37: 1658.8659 | C37: 1717.2182 | D37: 1792.2425 | E37: 1892.2749 | F37: 2032.3202 | G37: 2242.3883 | H37: 2592.5017
A38: 0.09 | B38: 1579.2569 | C38: 1625.088 | D38: 1682.3769 | E38: 1756.0341 | F38: 1854.2436 | G38: 1991.737 | H38: 2197.977
A39: 0.095 | B39: 1510.3556 | C39: 1547.1736 | D39: 1592.1733 | E39: 1648.423 | F39: 1720.744 | G39: 1817.172 | H39: 1952.1712
A40: 0.1 | B40: 1449.6279 | C40: 1479.7555 | D40: 1515.9086 | E40: 1560.0957 | F40: 1615.3296 | G40: 1686.3446 | H40: 1781.0313
A41: 0.105 | B41: 1395.3137 | C41: 1420.348 | D41: 1449.934 | E41: 1485.4372 | F41: 1528.8299 | G41: 1583.0709 | H41: 1652.8093
A42: 0.11 | B42: 1346.1511 | C42: 1367.225 | D42: 1391.8112 | E42: 1420.8677 | F42: 1455.7355 | G42: 1498.3517 | H42: 1551.6219
